Workbook

Sheet WTG
C1: 1 | D1: =+C1+1 -> 2 | E1: =+D1+1 -> 3 | F1: =+E1+1 -> 4 | G1: =+F1+1 -> 5 | H1: =+G1+1 -> 6 | I1: =+H1+1 -> 7 | J1: =+I1+1 -> 8 | K1: =+J1+1 -> 9 | ... AU1: =+AT1+1 -> 45
A2: Id | B2: WTG Model | C2: TS84 | D2: TS99 | E2: TS106 | F2: TS114 | G2: TS120 | H2: TS134 | I2: TCS134 | J2: TS78 | K2: TS83 | L2: TS90-00 | M2: TS110 | N2: TS125-02 | O2: TS135 | P2: TCS164 | Q2: TS105 | R2: TS108 | S2: TS108-05 | T2: TS125-01 | U2: TS145-01 | V2: TS155 | W2: TS100-00 | X2: TS105-01 | Y2: TS108-05 | Z2: TS125-04 | AA2: TS135-01 | AB2: TS155-02 | AC2: TC120N | AD2: TS118-00 | AE2: TS148-00 | AF2: TS159-00 | AG2: TCS164B | AH2: TCS168N | AI2: TS118-03 | AJ2: TS138 | AK2: TS148-01 | AL2: TS159-01 | AM2: TS112 | AN2: TS142-00 | AO2: TCS179-00 | AP2: TCS164N | AQ2: TS105-04 | AR2: TS108-04 | AS2: TS119 | AT2: TC100N | AU2: TS108-07
A3: 1 | B3: N131/3600 | C3: X | D3: X | E3: X | F3: X | G3: X | H3: X | I3: X
A4: =+A3+1 -> 2 | B4: N131/3000 | C4: X | D4: X | E4: X | F4: X | G4: X | H4: X | I4: X
A5: =+A4+1 -> 3 | B5: N131/3900 | C5: X | F5: X | G5: X | H5: X | I5: X
A6: =+A5+1 -> 4 | B6: N133/4.8 | J6: X | K6: X | L6: X | M6: X | N6: X | O6: X | P6: X
A7: =+A6+1 -> 5 | B7: N149/4.0 | O7: X | P7: X | Q7: X | R7: X | T7: X | U7: X | V7: X
A8: =+A7+1 -> 6 | B8: N149/4.5 | O8: X | P8: X | Q8: X | R8: X | T8: X | U8: X | V8: X
A9: =+A8+1 -> 7 | B9: N149/4.8 | O9: X | P9: X | Q9: X | R9: X | T9: X | U9: X | V9: X
A10: =+A9+1 -> 8 | B10: N149/5 | O10: X | P10: X | Q10: X | R10: X | T10: X | U10: X | V10: X
A11: =+A10+1 -> 9 | B11: N149/5.X | P11: X | W11: X | X11: X | Y11: X | Z11: X | AA11: X | AB11: X | AC11: X
A12: =+A11+1 -> 10 | B12: N163/5.X | Y12: x | AC12: X | AD12: X | AE12: X | AF12: X | AG12: X | AH12: X | AT12: X | AU12: X
A13: =+A12+1 -> 11 | B13: N163/6.X | P13: X | S13: X | AC13: X | AI13: X | AJ13: X | AK13: X | AL13: X | AS13: X | AT13: X | AU13: X
A14: =+A13+1 -> 12 | B14: N175/6.X | AM14: X | AN14: X | AO14: X
A15: 13 | B15: N155/4.X | Y15: X | AC15: X | AP15: X | AQ15: X | AR15: x
A16: 14 | B16: N155/5.X | Y16: X | AC16: X | AQ16: X | AT16: X

Sheet POWER MW
A2: Id-WTG | B2: WTG Model | C2: Power(MW) | D2: Q(VAR) | E2: S(MVA)
A3: =+MATCH(B3,WTG!$B$3:$B$16,0) -> 1 | B3: N131/3600 | C3: 3600 | D3: 1744 | E3: =+SQRT(C3*C3+D3*D3) -> 4000.192
A4: =+MATCH(B4,WTG!$B$3:$B$16,0) -> 2 | B4: N131/3000 | C4: 3000 | D4: 1598 | E4: =+SQRT(C4*C4+D4*D4) -> 3399.0593
A5: =+MATCH(B5,WTG!$B$3:$B$16,0) -> 3 | B5: N131/3900 | C5: 3900 | D5: 2400 | E5: =+SQRT(C5*C5+D5*D5) -> 4579.3013
A6: =+MATCH(B6,WTG!$B$3:$B$16,0) -> 4 | B6: N133/4.8 | C6: 4000 | D6: 2500 | E6: =+SQRT(C6*C6+D6*D6) -> 4716.9906
A7: =+MATCH(B7,WTG!$B$3:$B$16,0) -> 4 | B7: N133/4.8 | C7: 4380 | D7: 2500 | E7: =+SQRT(C7*C7+D7*D7) -> 5043.2529
A8: =+MATCH(B8,WTG!$B$3:$B$16,0) -> 4 | B8: N133/4.8 | C8: 4500 | D8: 2500 | E8: =+SQRT(C8*C8+D8*D8) -> 5147.8151
A9: =+MATCH(B9,WTG!$B$3:$B$16,0) -> 4 | B9: N133/4.8 | C9: 4800 | D9: 2610 | E9: =+SQRT(C9*C9+D9*D9) -> 5463.7075
A10: =+MATCH(B10,WTG!$B$3:$B$16,0) -> 5 | B10: N149/4.0 | C10: 4000 | D10: 2500 | E10: =+SQRT(C10*C10+D10*D10) -> 4716.9906
A11: =+MATCH(B11,WTG!$B$3:$B$16,0) -> 5 | B11: N149/4.0 | C11: 4380 | D11: 2500 | E11: =+SQRT(C11*C11+D11*D11) -> 5043.2529
A12: =+MATCH(B12,WTG!$B$3:$B$16,0) -> 5 | B12: N149/4.0 | C12: 4500 | D12: 2500 | E12: =+SQRT(C12*C12+D12*D12) -> 5147.8151
A13: =+MATCH(B13,WTG!$B$3:$B$16,0) -> 5 | B13: N149/4.0 | C13: 4800 | D13: 2610 | E13: =+SQRT(C13*C13+D13*D13) -> 5463.7075
A14: =+MATCH(B14,WTG!$B$3:$B$16,0) -> 6 | B14: N149/4.5 | C14: 4000 | D14: 2500 | E14: =+SQRT(C14*C14+D14*D14) -> 4716.9906
... A40: =+MATCH(B40,WTG!$B$3:$B$16,0) -> 14 | B40: N155/5.X | C40: 5700 | D40: 2345 | E40: =+SQRT(C40*C40+D40*D40) -> 6163.5237

Sheet TRANSFORM
C1: frequency 50hz | E1: Frecquency 60hz | G1: Powe Transformer (kVA)
A2: Id | B2: WTG Model | C2: NLL (KW) | D2: SCL (kW) | E2: NLL (KW) | F2: SCL (kW)
A3: =+MATCH(B3,WTG!$B$3:$B$16,0) -> 1 | B3: =+WTG!B3 -> N131/3600 | C3: 2400 | D3: 58000 | E3: 4000 | F3: 60000 | G3: 5350
A4: =+MATCH(B4,WTG!$B$3:$B$16,0) -> 2 | B4: =+WTG!B4 -> N131/3000 | C4: 2400 | D4: 58000 | E4: 4000 | F4: 60000 | G4: 5350
A5: =+MATCH(B5,WTG!$B$3:$B$16,0) -> 3 | B5: =+WTG!B5 -> N131/3900 | C5: 2400 | D5: 58000 | E5: 4000 | F5: 60000 | G5: 5350
A6: =+MATCH(B6,WTG!$B$3:$B$16,0) -> 4 | B6: =+WTG!B6 -> N133/4.8 | C6: 2400 | D6: 58000 | E6: 4000 | F6: 60000 | G6: 5350
A7: =+MATCH(B7,WTG!$B$3:$B$16,0) -> 5 | B7: =+WTG!B7 -> N149/4.0 | C7: 2400 | D7: 58000 | E7: 4000 | F7: 60000 | G7: 4500
A8: =+MATCH(B8,WTG!$B$3:$B$16,0) -> 6 | B8: =+WTG!B8 -> N149/4.5 | C8: 2400 | D8: 58000 | E8: 4000 | F8: 60000 | G8: 4500
A9: =+MATCH(B9,WTG!$B$3:$B$16,0) -> 7 | B9: =+WTG!B9 -> N149/4.8 | C9: 2400 | D9: 58000 | E9: 4000 | F9: 60000 | G9: 5350
A10: =+MATCH(B10,WTG!$B$3:$B$16,0) -> 8 | B10: =+WTG!B10 -> N149/5 | C10: 2400 | D10: 58000 | E10: 4000 | F10: 60000 | G10: 5350
A11: =+MATCH(B11,WTG!$B$3:$B$16,0) -> 9 | B11: =+WTG!B11 -> N149/5.X | C11: 2900 | D11: 70000 | E11: 4000 | F11: 71000 | G11: 5350
A12: =+MATCH(B12,WTG!$B$3:$B$16,0) -> 10 | B12: =+WTG!B12 -> N163/5.X | C12: 2900 | D12: 70000 | E12: 4000 | F12: 71000 | G12: 6350
A13: =+MATCH(B13,WTG!$B$3:$B$16,0) -> 11 | B13: =+WTG!B13 -> N163/6.X | C13: 3050 | D13: 80000 | E13: 4300 | F13: 80700 | G13: 7800
A14: =+MATCH(B14,WTG!$B$3:$B$16,0) -> 12 | B14: =+WTG!B14 -> N175/6.X | C14: 3050 | D14: 80000 | E14: 4300 | F14: 80700 | G14: 7800
A15: =+MATCH(B15,WTG!$B$3:$B$16,0) -> 13 | B15: =+WTG!B15 -> N155/4.X | C15: 4000 | D15: 60000 | E15: 4000 | F15: 60000 | G15: 5350

Sheet DIAMETER_BLADE
A2: Id | B2: WTG Model | C2: Diemeter rotor(m)
A3: =+MATCH(B3,WTG!$B$3:$B$16,0) -> 1 | B3: =+WTG!B3 -> N131/3600 | C3: 131
A4: =+MATCH(B4,WTG!$B$3:$B$16,0) -> 2 | B4: =+WTG!B4 -> N131/3000 | C4: 131
A5: =+MATCH(B5,WTG!$B$3:$B$16,0) -> 3 | B5: =+WTG!B5 -> N131/3900 | C5: 131
A6: =+MATCH(B6,WTG!$B$3:$B$16,0) -> 4 | B6: =+WTG!B6 -> N133/4.8 | C6: 133.2
A7: =+MATCH(B7,WTG!$B$3:$B$16,0) -> 5 | B7: =+WTG!B7 -> N149/4.0 | C7: 149.1
A8: =+MATCH(B8,WTG!$B$3:$B$16,0) -> 6 | B8: =+WTG!B8 -> N149/4.5 | C8: 149.1
A9: =+MATCH(B9,WTG!$B$3:$B$16,0) -> 7 | B9: =+WTG!B9 -> N149/4.8 | C9: 149.1
A10: =+MATCH(B10,WTG!$B$3:$B$16,0) -> 8 | B10: =+WTG!B10 -> N149/5 | C10: 149.1
A11: =+MATCH(B11,WTG!$B$3:$B$16,0) -> 9 | B11: =+WTG!B11 -> N149/5.X | C11: 149.1
A12: =+MATCH(B12,WTG!$B$3:$B$16,0) -> 10 | B12: =+WTG!B12 -> N163/5.X | C12: 149.1
A13: =+MATCH(B13,WTG!$B$3:$B$16,0) -> 11 | B13: =+WTG!B13 -> N163/6.X | C13: 149.1
A14: =+MATCH(B14,WTG!$B$3:$B$16,0) -> 12 | B14: =+WTG!B14 -> N175/6.X | C14: 175
A15: =+MATCH(B15,WTG!$B$3:$B$16,0) -> 13 | B15: =+WTG!B15 -> N155/4.X | C15: 155
A16: =+MATCH(B16,WTG!$B$3:$B$16,0) -> 14 | B16: N155/5.X | C16: 155

Sheet PLATFORM
D1: ROAD PAD | H1: CRANE BOOM PAD | L1: BLADES PAD | P1: ROAD EXTENSION | T1: CRANE PAD 1 | X1: CRANE PAD 2 | AB1: Preassembly 1 | AE1: Preassembly 2 | AH1: Preassembly 3 | AK1: Preassembly 4 | AN1: Preassembly 5 | AQ1: Preassembly 6 | AT1: Diameter | AU1: entry | AW1: out
A2: ID Platform | C2: Wide road | D2: x1 | E2: y1 | F2: x2 | G2: y2 | H2: x1 | I2: y1 | J2: x2 | K2: y2 | L2: x1 | M2: y1 | N2: x2 | O2: y2 | P2: x1 | Q2: y1 | R2: x2 | S2: y2 | T2: x1 | U2: y1 | V2: x2 | W2: y2 | X2: x1 | Y2: y1 | Z2: x2 | AA2: y2 | AB2: x center | AC2: y center | AD2: radio | AE2: x center | AF2: y center | AG2: radio | AH2: x center | AI2: y center | AJ2: radio | AK2: x center | AL2: y center | AM2: radio | AN2: x center | AO2: y center | AP2: radio | AQ2: x center | AR2: y center | AS2: radio | AU2: x | AV2: y | AW2: x | AX2: y | AY2: Area Road Pad | AZ2: Area Crane Bon Pad | BA2: Area Blades Pad | BB2: Area Road Extension | BC2: Area Crane Pad | BD2: Area Preassembly | BE2: Total area Platform
A3: 1 | B3: TS84 | C3: 6 | D3: -160.645 | E3: -21 | F3: 38.065 | G3: -15 | H3: -147.5 | I3: -15 | J3: -50.55 | K3: 0 | L3: -71.5 | M3: -40 | N3: 4.5 | O3: -25 | P3: -71.5 | Q3: -25 | R3: 4.5 | S3: -21 | T3: -50.5 | U3: -15 | V3: -5.5 | W3: 8.12 | X3: -50.55 | Y3: 8 | Z3: -29.501 | AA3: 20 | AB3: -8.748 | AC3: 9.63 | AD3: 4.6 | AE3: 0 | AF3: 10.173 | AG3: 4 | AH3: -1.9 | AI3: -9.728 | AJ3: 3.7 | AK3: 5.19 | AL3: -7.65 | AM3: 3.2 | AT3: 5.5 | AU3: =+D3 -> -160.645 | AV3: =-C3/2+E3 -> -24 | AW3: =+F3 -> 38.065 | AX3: =-C3/2+E3 -> -24 | AY3: =+ABS((D3-F3)*(E3-G3)) -> 1192.26 | AZ3: =+ABS((H3-J3)*(I3-K3)) -> 1454.25 | BA3: =+ABS((L3-N3)*(M3-O3)) -> 1140 | BB3: =+(P3-R3)*(Q3-S3) -> 304 | BC3: =+ABS((T3-V3)*(U3-W3))+ABS((X3-Z3)*(Y3-AA3)) -> 1292.988 | BD3: =+PI()*((AD3+3)^2+(AG3+3)^2+(AJ3+3)^2+(AM3+3)^2+(AP3+3)^2+(AS3+3)^2) -> 653.73402 | BE3: =+SUM(AY3:BD3) -> 6037.232
A4: =+A3+1 -> 2 | B4: TS99 | C4: 6 | D4: -160.645 | E4: -21 | F4: 38.065 | G4: -15 | H4: -147.5 | I4: -15 | J4: -50.55 | K4: 0 | L4: -71.5 | M4: -40 | N4: 4.5 | O4: -25 | P4: -71.5 | Q4: -25 | R4: 4.5 | S4: -21 | T4: -50.5 | U4: -15 | V4: -5.5 | W4: 8.12 | X4: -50.55 | Y4: 8 | Z4: -29.501 | AA4: 20 | AB4: -8.748 | AC4: 9.63 | AD4: 4.6 | AE4: 0 | AF4: 10.173 | AG4: 4 | AH4: -1.9 | AI4: -9.728 | AJ4: 3.7 | AK4: 5.19 | AL4: -7.65 | AM4: 3.2 | AT4: 5.5 | AU4: =+D4 -> -160.645 | AV4: =-C4/2+E4 -> -24 | AW4: =+F4 -> 38.065 | AX4: =-C4/2+E4 -> -24 | AY4: =+ABS((D4-F4)*(E4-G4)) -> 1192.26 | AZ4: =+ABS((H4-J4)*(I4-K4)) -> 1454.25 | BA4: =+ABS((L4-N4)*(M4-O4)) -> 1140 | BB4: =+(P4-R4)*(Q4-S4) -> 304 | BC4: =+ABS((T4-V4)*(U4-W4))+ABS((X4-Z4)*(Y4-AA4)) -> 1292.988 | BD4: =+PI()*((AD4+3)^2+(AG4+3)^2+(AJ4+3)^2+(AM4+3)^2+(AP4+3)^2+(AS4+3)^2) -> 653.73402 | BE4: =+SUM(AY4:BD4) -> 6037.232
A5: =+A4+1 -> 3 | B5: TS106 | C5: 6 | D5: -160.645 | E5: -21 | F5: 38.065 | G5: -15 | H5: -147.5 | I5: -15 | J5: -50.55 | K5: 0 | L5: -71.5 | M5: -40 | N5: 4.5 | O5: -25 | P5: -71.5 | Q5: -25 | R5: 4.5 | S5: -21 | T5: -50.5 | U5: -15 | V5: -5.5 | W5: 8.12 | X5: -50.55 | Y5: 8 | Z5: -29.501 | AA5: 20 | AB5: -8.748 | AC5: 9.63 | AD5: 4.6 | AE5: 0 | AF5: 10.173 | AG5: 4 | AH5: -1.9 | AI5: -9.728 | AJ5: 3.7 | AK5: 5.19 | AL5: -7.65 | AM5: 3.2 | AT5: 5.5 | AU5: =+D5 -> -160.645 | AV5: =-C5/2+E5 -> -24 | AW5: =+F5 -> 38.065 | AX5: =-C5/2+E5 -> -24 | AY5: =+ABS((D5-F5)*(E5-G5)) -> 1192.26 | AZ5: =+ABS((H5-J5)*(I5-K5)) -> 1454.25 | BA5: =+ABS((L5-N5)*(M5-O5)) -> 1140 | BB5: =+(P5-R5)*(Q5-S5) -> 304 | BC5: =+ABS((T5-V5)*(U5-W5))+ABS((X5-Z5)*(Y5-AA5)) -> 1292.988 | BD5: =+PI()*((AD5+3)^2+(AG5+3)^2+(AJ5+3)^2+(AM5+3)^2+(AP5+3)^2+(AS5+3)^2) -> 653.73402 | BE5: =+SUM(AY5:BD5) -> 6037.232
A6: =+A5+1 -> 4 | B6: TS114 | C6: 6 | D6: -160.645 | E6: -21 | F6: 38.065 | G6: -15 | H6: -147.5 | I6: -15 | J6: -50.55 | K6: 0 | L6: -71.5 | M6: -40 | N6: 4.5 | O6: -25 | P6: -71.5 | Q6: -25 | R6: 4.5 | S6: -21 | T6: -50.5 | U6: -15 | V6: -5.5 | W6: 8.12 | X6: -50.55 | Y6: 8 | Z6: -29.501 | AA6: 20 | AB6: -8.748 | AC6: 9.63 | AD6: 4.6 | AE6: 0 | AF6: 10.173 | AG6: 4 | AH6: -1.9 | AI6: -9.728 | AJ6: 3.7 | AK6: 5.19 | AL6: -7.65 | AM6: 3.2 | AT6: 5.5 | AU6: =+D6 -> -160.645 | AV6: =-C6/2+E6 -> -24 | AW6: =+F6 -> 38.065 | AX6: =-C6/2+E6 -> -24 | AY6: =+ABS((D6-F6)*(E6-G6)) -> 1192.26 | AZ6: =+ABS((H6-J6)*(I6-K6)) -> 1454.25 | BA6: =+ABS((L6-N6)*(M6-O6)) -> 1140 | BB6: =+(P6-R6)*(Q6-S6) -> 304 | BC6: =+ABS((T6-V6)*(U6-W6))+ABS((X6-Z6)*(Y6-AA6)) -> 1292.988 | BD6: =+PI()*((AD6+3)^2+(AG6+3)^2+(AJ6+3)^2+(AM6+3)^2+(AP6+3)^2+(AS6+3)^2) -> 653.73402 | BE6: =+SUM(AY6:BD6) -> 6037.232
A7: =+A6+1 -> 5 | B7: TS120 | C7: 6 | D7: -160.645 | E7: -21 | F7: 38.065 | G7: -15 | H7: -147.5 | I7: -15 | J7: -50.55 | K7: 0 | L7: -71.5 | M7: -40 | N7: 4.5 | O7: -25 | P7: -71.5 | Q7: -25 | R7: 4.5 | S7: -21 | T7: -50.5 | U7: -15 | V7: -5.5 | W7: 8.12 | X7: -50.55 | Y7: 8 | Z7: -29.501 | AA7: 20 | AB7: -8.748 | AC7: 9.63 | AD7: 4.6 | AE7: 0 | AF7: 10.173 | AG7: 4 | AH7: -1.9 | AI7: -9.728 | AJ7: 3.7 | AK7: 5.19 | AL7: -7.65 | AM7: 3.2 | AT7: 5.5 | AU7: =+D7 -> -160.645 | AV7: =-C7/2+E7 -> -24 | AW7: =+F7 -> 38.065 | AX7: =-C7/2+E7 -> -24 | AY7: =+ABS((D7-F7)*(E7-G7)) -> 1192.26 | AZ7: =+ABS((H7-J7)*(I7-K7)) -> 1454.25 | BA7: =+ABS((L7-N7)*(M7-O7)) -> 1140 | BB7: =+(P7-R7)*(Q7-S7) -> 304 | BC7: =+ABS((T7-V7)*(U7-W7))+ABS((X7-Z7)*(Y7-AA7)) -> 1292.988 | BD7: =+PI()*((AD7+3)^2+(AG7+3)^2+(AJ7+3)^2+(AM7+3)^2+(AP7+3)^2+(AS7+3)^2) -> 653.73402 | BE7: =+SUM(AY7:BD7) -> 6037.232
A8: =+A7+1 -> 6 | B8: TS134 | C8: 6 | D8: -160.645 | E8: -21 | F8: 38.065 | G8: -15 | H8: -147.5 | I8: -15 | J8: -50.55 | K8: 0 | L8: -71.5 | M8: -40 | N8: 4.5 | O8: -25 | P8: -71.5 | Q8: -25 | R8: 4.5 | S8: -21 | T8: -50.5 | U8: -15 | V8: -5.5 | W8: 8.12 | X8: -50.55 | Y8: 8 | Z8: -29.501 | AA8: 20 | AB8: -8.748 | AC8: 9.63 | AD8: 4.6 | AE8: 0 | AF8: 10.173 | AG8: 4 | AH8: -1.9 | AI8: -9.728 | AJ8: 3.7 | AK8: 5.19 | AL8: -7.65 | AM8: 3.2 | AT8: 5.5 | AU8: =+D8 -> -160.645 | AV8: =-C8/2+E8 -> -24 | AW8: =+F8 -> 38.065 | AX8: =-C8/2+E8 -> -24 | AY8: =+ABS((D8-F8)*(E8-G8)) -> 1192.26 | AZ8: =+ABS((H8-J8)*(I8-K8)) -> 1454.25 | BA8: =+ABS((L8-N8)*(M8-O8)) -> 1140 | BB8: =+(P8-R8)*(Q8-S8) -> 304 | BC8: =+ABS((T8-V8)*(U8-W8))+ABS((X8-Z8)*(Y8-AA8)) -> 1292.988 | BD8: =+PI()*((AD8+3)^2+(AG8+3)^2+(AJ8+3)^2+(AM8+3)^2+(AP8+3)^2+(AS8+3)^2) -> 653.73402 | BE8: =+SUM(AY8:BD8) -> 6037.232
A9: =+A8+1 -> 7 | B9: TCS134 | C9: 6 | D9: -160.645 | E9: -21 | F9: 38.065 | G9: -15 | H9: -147.5 | I9: -15 | J9: -50.55 | K9: 0 | L9: -71.5 | M9: -40 | N9: 4.5 | O9: -25 | P9: -71.5 | Q9: -25 | R9: 4.5 | S9: -21 | T9: -50.5 | U9: -15 | V9: -5.5 | W9: 8.12 | X9: -50.55 | Y9: 8 | Z9: -29.501 | AA9: 20 | AB9: -8.748 | AC9: 9.63 | AD9: 4.6 | AE9: 0 | AF9: 10.173 | AG9: 4 | AH9: -1.9 | AI9: -9.728 | AJ9: 3.7 | AK9: 5.19 | AL9: -7.65 | AM9: 3.2 | AT9: 5.5 | AU9: =+D9 -> -160.645 | AV9: =-C9/2+E9 -> -24 | AW9: =+F9 -> 38.065 | AX9: =-C9/2+E9 -> -24 | AY9: =+ABS((D9-F9)*(E9-G9)) -> 1192.26 | AZ9: =+ABS((H9-J9)*(I9-K9)) -> 1454.25 | BA9: =+ABS((L9-N9)*(M9-O9)) -> 1140 | BB9: =+(P9-R9)*(Q9-S9) -> 304 | BC9: =+ABS((T9-V9)*(U9-W9))+ABS((X9-Z9)*(Y9-AA9)) -> 1292.988 | BD9: =+PI()*((AD9+3)^2+(AG9+3)^2+(AJ9+3)^2+(AM9+3)^2+(AP9+3)^2+(AS9+3)^2) -> 653.73402 | BE9: =+SUM(AY9:BD9) -> 6037.232
A10: =+A9+1 -> 8 | B10: TS78 | C10: 6 | D10: -160.645 | E10: -21 | F10: 38.065 | G10: -15 | H10: -147.5 | I10: -15 | J10: -50.55 | K10: 0 | L10: -71.5 | M10: -40 | N10: 4.5 | O10: -25 | P10: -71.5 | Q10: -25 | R10: 4.5 | S10: -21 | T10: -50.5 | U10: -15 | V10: -5.5 | W10: 8.12 | X10: -50.55 | Y10: 8 | Z10: -29.501 | AA10: 20 | AB10: -8.748 | AC10: 9.63 | AD10: 4.6 | AE10: 0 | AF10: 10.173 | AG10: 4 | AH10: -1.9 | AI10: -9.728 | AJ10: 3.7 | AK10: 5.19 | AL10: -7.65 | AM10: 3.2 | AT10: 5.5 | AU10: =+D10 -> -160.645 | AV10: =-C10/2+E10 -> -24 | AW10: =+F10 -> 38.065 | AX10: =-C10/2+E10 -> -24 | AY10: =+ABS((D10-F10)*(E10-G10)) -> 1192.26 | AZ10: =+ABS((H10-J10)*(I10-K10)) -> 1454.25 | BA10: =+ABS((L10-N10)*(M10-O10)) -> 1140 | BB10: =+(P10-R10)*(Q10-S10) -> 304 | BC10: =+ABS((T10-V10)*(U10-W10))+ABS((X10-Z10)*(Y10-AA10)) -> 1292.988 | BD10: =+PI()*((AD10+3)^2+(AG10+3)^2+(AJ10+3)^2+(AM10+3)^2+(AP10+3)^2+(AS10+3)^2) -> 653.73402 | BE10: =+SUM(AY10:BD10) -> 6037.232
A11: =+A10+1 -> 9 | B11: TS83 | C11: 6 | D11: -160.645 | E11: -21 | F11: 38.065 | G11: -15 | H11: -147.5 | I11: -15 | J11: -50.55 | K11: 0 | L11: -71.5 | M11: -40 | N11: 4.5 | O11: -25 | P11: -71.5 | Q11: -25 | R11: 4.5 | S11: -21 | T11: -50.5 | U11: -15 | V11: -5.5 | W11: 8.12 | X11: -50.55 | Y11: 8 | Z11: -29.501 | AA11: 20 | AB11: -8.748 | AC11: 9.63 | AD11: 4.6 | AE11: 0 | AF11: 10.173 | AG11: 4 | AH11: -1.9 | AI11: -9.728 | AJ11: 3.7 | AK11: 5.19 | AL11: -7.65 | AM11: 3.2 | AT11: 5.5 | AU11: =+D11 -> -160.645 | AV11: =-C11/2+E11 -> -24 | AW11: =+F11 -> 38.065 | AX11: =-C11/2+E11 -> -24 | AY11: =+ABS((D11-F11)*(E11-G11)) -> 1192.26 | AZ11: =+ABS((H11-J11)*(I11-K11)) -> 1454.25 | BA11: =+ABS((L11-N11)*(M11-O11)) -> 1140 | BB11: =+(P11-R11)*(Q11-S11) -> 304 | BC11: =+ABS((T11-V11)*(U11-W11))+ABS((X11-Z11)*(Y11-AA11)) -> 1292.988 | BD11: =+PI()*((AD11+3)^2+(AG11+3)^2+(AJ11+3)^2+(AM11+3)^2+(AP11+3)^2+(AS11+3)^2) -> 653.73402 | BE11: =+SUM(AY11:BD11) -> 6037.232
A12: =+A11+1 -> 10 | B12: TS90-00 | C12: 6 | D12: -160.645 | E12: -21 | F12: 38.065 | G12: -15 | H12: -147.5 | I12: -15 | J12: -50.55 | K12: 0 | L12: -71.5 | M12: -40 | N12: 4.5 | O12: -25 | P12: -71.5 | Q12: -25 | R12: 4.5 | S12: -21 | T12: -50.5 | U12: -15 | V12: -5.5 | W12: 8.12 | X12: -50.55 | Y12: 8 | Z12: -29.501 | AA12: 20 | AB12: -8.748 | AC12: 9.63 | AD12: 4.6 | AE12: 0 | AF12: 10.173 | AG12: 4 | AH12: -1.9 | AI12: -9.728 | AJ12: 3.7 | AK12: 5.19 | AL12: -7.65 | AM12: 3.2 | AT12: 5.5 | AU12: =+D12 -> -160.645 | AV12: =-C12/2+E12 -> -24 | AW12: =+F12 -> 38.065 | AX12: =-C12/2+E12 -> -24 | AY12: =+ABS((D12-F12)*(E12-G12)) -> 1192.26 | AZ12: =+ABS((H12-J12)*(I12-K12)) -> 1454.25 | BA12: =+ABS((L12-N12)*(M12-O12)) -> 1140 | BB12: =+(P12-R12)*(Q12-S12) -> 304 | BC12: =+ABS((T12-V12)*(U12-W12))+ABS((X12-Z12)*(Y12-AA12)) -> 1292.988 | BD12: =+PI()*((AD12+3)^2+(AG12+3)^2+(AJ12+3)^2+(AM12+3)^2+(AP12+3)^2+(AS12+3)^2) -> 653.73402 | BE12: =+SUM(AY12:BD12) -> 6037.232
A13: =+A12+1 -> 11 | B13: TS110 | C13: 6 | D13: -160.645 | E13: -21 | F13: 38.065 | G13: -15 | H13: -147.5 | I13: -15 | J13: -50.55 | K13: 0 | L13: -71.5 | M13: -40 | N13: 4.5 | O13: -25 | P13: -71.5 | Q13: -25 | R13: 4.5 | S13: -21 | T13: -50.5 | U13: -15 | V13: -5.5 | W13: 8.12 | X13: -50.55 | Y13: 8 | Z13: -29.501 | AA13: 20 | AB13: -8.748 | AC13: 9.63 | AD13: 4.6 | AE13: 0 | AF13: 10.173 | AG13: 4 | AH13: -1.9 | AI13: -9.728 | AJ13: 3.7 | AK13: 5.19 | AL13: -7.65 | AM13: 3.2 | AT13: 5.5 | AU13: =+D13 -> -160.645 | AV13: =-C13/2+E13 -> -24 | AW13: =+F13 -> 38.065 | AX13: =-C13/2+E13 -> -24 | AY13: =+ABS((D13-F13)*(E13-G13)) -> 1192.26 | AZ13: =+ABS((H13-J13)*(I13-K13)) -> 1454.25 | BA13: =+ABS((L13-N13)*(M13-O13)) -> 1140 | BB13: =+(P13-R13)*(Q13-S13) -> 304 | BC13: =+ABS((T13-V13)*(U13-W13))+ABS((X13-Z13)*(Y13-AA13)) -> 1292.988 | BD13: =+PI()*((AD13+3)^2+(AG13+3)^2+(AJ13+3)^2+(AM13+3)^2+(AP13+3)^2+(AS13+3)^2) -> 653.73402 | BE13: =+SUM(AY13:BD13) -> 6037.232
A14: =+A13+1 -> 12 | B14: TS125-02 | C14: 6 | D14: -160.645 | E14: -21 | F14: 38.065 | G14: -15 | H14: -147.5 | I14: -15 | J14: -50.55 | K14: 0 | L14: -71.5 | M14: -40 | N14: 4.5 | O14: -25 | P14: -71.5 | Q14: -25 | R14: 4.5 | S14: -21 | T14: -50.5 | U14: -15 | V14: -5.5 | W14: 8.12 | X14: -50.55 | Y14: 8 | Z14: -29.501 | AA14: 20 | AB14: -8.748 | AC14: 9.63 | AD14: 4.6 | AE14: 0 | AF14: 10.173 | AG14: 4 | AH14: -1.9 | AI14: -9.728 | AJ14: 3.7 | AK14: 5.19 | AL14: -7.65 | AM14: 3.2 | AT14: 5.5 | AU14: =+D14 -> -160.645 | AV14: =-C14/2+E14 -> -24 | AW14: =+F14 -> 38.065 | AX14: =-C14/2+E14 -> -24 | AY14: =+ABS((D14-F14)*(E14-G14)) -> 1192.26 | AZ14: =+ABS((H14-J14)*(I14-K14)) -> 1454.25 | BA14: =+ABS((L14-N14)*(M14-O14)) -> 1140 | BB14: =+(P14-R14)*(Q14-S14) -> 304 | BC14: =+ABS((T14-V14)*(U14-W14))+ABS((X14-Z14)*(Y14-AA14)) -> 1292.988 | BD14: =+PI()*((AD14+3)^2+(AG14+3)^2+(AJ14+3)^2+(AM14+3)^2+(AP14+3)^2+(AS14+3)^2) -> 653.73402 | BE14: =+SUM(AY14:BD14) -> 6037.232
A15: =+A14+1 -> 13 | B15: TS135 | C15: 6 | D15: -160.645 | E15: -21 | F15: 38.065 | G15: -15 | H15: -147.5 | I15: -15 | J15: -50.55 | K15: 0 | L15: -71.5 | M15: -40 | N15: 4.5 | O15: -25 | P15: -71.5 | Q15: -25 | R15: 4.5 | S15: -21 | T15: -50.5 | U15: -15 | V15: -5.5 | W15: 8.12 | X15: -50.55 | Y15: 8 | Z15: -29.501 | AA15: 20 | AB15: -8.748 | AC15: 9.63 | AD15: 4.6 | AE15: 0 | AF15: 10.173 | AG15: 4 | AH15: -1.9 | AI15: -9.728 | AJ15: 3.7 | AK15: 5.19 | AL15: -7.65 | AM15: 3.2 | AT15: 5.5 | AU15: =+D15 -> -160.645 | AV15: =-C15/2+E15 -> -24 | AW15: =+F15 -> 38.065 | AX15: =-C15/2+E15 -> -24 | AY15: =+ABS((D15-F15)*(E15-G15)) -> 1192.26 | AZ15: =+ABS((H15-J15)*(I15-K15)) -> 1454.25 | BA15: =+ABS((L15-N15)*(M15-O15)) -> 1140 | BB15: =+(P15-R15)*(Q15-S15) -> 304 | BC15: =+ABS((T15-V15)*(U15-W15))+ABS((X15-Z15)*(Y15-AA15)) -> 1292.988 | BD15: =+PI()*((AD15+3)^2+(AG15+3)^2+(AJ15+3)^2+(AM15+3)^2+(AP15+3)^2+(AS15+3)^2) -> 653.73402 | BE15: =+SUM(AY15:BD15) -> 6037.232
... A18: =+A17+1 -> 16 | B18: TS108 | C18: 6 | D18: -160.645 | E18: -21 | F18: 38.065 | G18: -15 | H18: -147.5 | I18: -15 | J18: -50.55 | K18: 0 | L18: -71.5 | M18: -40 | N18: 4.5 | O18: -25 | P18: -71.5 | Q18: -25 | R18: 4.5 | S18: -21 | T18: -50.5 | U18: -15 | V18: -5.5 | W18: 8.12 | X18: -50.55 | Y18: 8 | Z18: -29.501 | AA18: 20 | AB18: -8.748 | AC18: 9.63 | AD18: 4.6 | AE18: 0 | AF18: 10.173 | AG18: 4 | AH18: -1.9 | AI18: -9.728 | AJ18: 3.7 | AK18: 5.19 | AL18: -7.65 | AM18: 3.2 | AT18: 5.5 | AU18: =+D18 -> -160.645 | AV18: =-C18/2+E18 -> -24 | AW18: =+F18 -> 38.065 | AX18: =-C18/2+E18 -> -24 | AY18: =+ABS((D18-F18)*(E18-G18)) -> 1192.26 | AZ18: =+ABS((H18-J18)*(I18-K18)) -> 1454.25 | BA18: =+ABS((L18-N18)*(M18-O18)) -> 1140 | BB18: =+(P18-R18)*(Q18-S18) -> 304 | BC18: =+ABS((T18-V18)*(U18-W18))+ABS((X18-Z18)*(Y18-AA18)) -> 1292.988 | BD18: =+PI()*((AD18+3)^2+(AG18+3)^2+(AJ18+3)^2+(AM18+3)^2+(AP18+3)^2+(AS18+3)^2) -> 653.73402 | BE18: =+SUM(AY18:BD18) -> 6037.232
A19: =+A18+1 -> 17 | B19: TS108-05 | C19: 6 | D19: -173.95 | E19: 15 | F19: 50.6943 | G19: 21 | H19: -150 | I19: 15 | J19: -44.5 | K19: 3 | L19: -85.88 | M19: 43.5 | N19: -3 | O19: 26.5 | P19: -75 | Q19: 26.5 | R19: 7 | S19: 21 | T19: -45 | U19: 15 | V19: -8 | W19: -4 | X19: -45 | Y19: -4 | Z19: -3 | AA19: -24 | AT19: 16 | AU19: =+D19 -> -173.95 | AV19: =-C19/2+E19 -> 12 | AW19: =+F19 -> 50.6943 | AX19: =-C19/2+E19 -> 12 | AY19: =+ABS((D19-F19)*(E19-G19)) -> 1347.8658 | AZ19: =+ABS((H19-J19)*(I19-K19)) -> 1266 | BA19: =+ABS((L19-N19)*(M19-O19)) -> 1408.96 | BB19: =+(P19-R19)*(Q19-S19) -> -451 | BC19: =+ABS((T19-V19)*(U19-W19))+ABS((X19-Z19)*(Y19-AA19)) -> 1543 | BD19: =+PI()*((AD19+3)^2+(AG19+3)^2+(AJ19+3)^2+(AM19+3)^2+(AP19+3)^2+(AS19+3)^2) -> 169.646 | BE19: =+SUM(AY19:BD19) -> 5284.4718
A20: =+A19+1 -> 18 | B20: TS125-01 | C20: 6 | D20: -173.95 | E20: 15 | F20: 50.6943 | G20: 21 | H20: -150 | I20: 15 | J20: -44.5 | K20: 3 | L20: -85.88 | M20: 43.5 | N20: -3 | O20: 26.5 | P20: -75 | Q20: 26.5 | R20: 7 | S20: 21 | T20: -45 | U20: 15 | V20: -8 | W20: -4 | X20: -45 | Y20: -4 | Z20: -3 | AA20: -24 | AT20: 16 | AU20: =+D20 -> -173.95 | AV20: =-C20/2+E20 -> 12 | AW20: =+F20 -> 50.6943 | AX20: =-C20/2+E20 -> 12 | AY20: =+ABS((D20-F20)*(E20-G20)) -> 1347.8658 | AZ20: =+ABS((H20-J20)*(I20-K20)) -> 1266 | BA20: =+ABS((L20-N20)*(M20-O20)) -> 1408.96 | BB20: =+(P20-R20)*(Q20-S20) -> -451 | BC20: =+ABS((T20-V20)*(U20-W20))+ABS((X20-Z20)*(Y20-AA20)) -> 1543 | BD20: =+PI()*((AD20+3)^2+(AG20+3)^2+(AJ20+3)^2+(AM20+3)^2+(AP20+3)^2+(AS20+3)^2) -> 169.646 | BE20: =+SUM(AY20:BD20) -> 5284.4718
A21: =+A20+1 -> 19 | B21: TS145-01 | C21: 6 | D21: -173.95 | E21: 15 | F21: 50.6943 | G21: 21 | H21: -150 | I21: 15 | J21: -44.5 | K21: 3 | L21: -85.88 | M21: 43.5 | N21: -3 | O21: 26.5 | P21: -75 | Q21: 26.5 | R21: 7 | S21: 21 | T21: -45 | U21: 15 | V21: -8 | W21: -4 | X21: -45 | Y21: -4 | Z21: -3 | AA21: -24 | AT21: 16 | AU21: =+D21 -> -173.95 | AV21: =-C21/2+E21 -> 12 | AW21: =+F21 -> 50.6943 | AX21: =-C21/2+E21 -> 12 | AY21: =+ABS((D21-F21)*(E21-G21)) -> 1347.8658 | AZ21: =+ABS((H21-J21)*(I21-K21)) -> 1266 | BA21: =+ABS((L21-N21)*(M21-O21)) -> 1408.96 | BB21: =+(P21-R21)*(Q21-S21) -> -451 | BC21: =+ABS((T21-V21)*(U21-W21))+ABS((X21-Z21)*(Y21-AA21)) -> 1543 | BD21: =+PI()*((AD21+3)^2+(AG21+3)^2+(AJ21+3)^2+(AM21+3)^2+(AP21+3)^2+(AS21+3)^2) -> 169.646 | BE21: =+SUM(AY21:BD21) -> 5284.4718
A22: =+A21+1 -> 20 | B22: TS155 | C22: 6 | D22: -173.95 | E22: 15 | F22: 50.6943 | G22: 21 | H22: -150 | I22: 15 | J22: -44.5 | K22: 3 | L22: -85.88 | M22: 43.5 | N22: -3 | O22: 26.5 | P22: -75 | Q22: 26.5 | R22: 7 | S22: 21 | T22: -45 | U22: 15 | V22: -8 | W22: -4 | X22: -45 | Y22: -4 | Z22: -3 | AA22: -24 | AT22: 16 | AU22: =+D22 -> -173.95 | AV22: =-C22/2+E22 -> 12 | AW22: =+F22 -> 50.6943 | AX22: =-C22/2+E22 -> 12 | AY22: =+ABS((D22-F22)*(E22-G22)) -> 1347.8658 | AZ22: =+ABS((H22-J22)*(I22-K22)) -> 1266 | BA22: =+ABS((L22-N22)*(M22-O22)) -> 1408.96 | BB22: =+(P22-R22)*(Q22-S22) -> -451 | BC22: =+ABS((T22-V22)*(U22-W22))+ABS((X22-Z22)*(Y22-AA22)) -> 1543 | BD22: =+PI()*((AD22+3)^2+(AG22+3)^2+(AJ22+3)^2+(AM22+3)^2+(AP22+3)^2+(AS22+3)^2) -> 169.646 | BE22: =+SUM(AY22:BD22) -> 5284.4718
A23: =+A22+1 -> 21 | B23: TS100-00 | C23: 6 | D23: -173.95 | E23: 15 | F23: 50.6943 | G23: 21 | H23: -150 | I23: 15 | J23: -44.5 | K23: 3 | L23: -85.88 | M23: 43.5 | N23: -3 | O23: 26.5 | P23: -75 | Q23: 26.5 | R23: 7 | S23: 21 | T23: -45 | U23: 15 | V23: -8 | W23: -4 | X23: -45 | Y23: -4 | Z23: -3 | AA23: -24 | AT23: 16 | AU23: =+D23 -> -173.95 | AV23: =-C23/2+E23 -> 12 | AW23: =+F23 -> 50.6943 | AX23: =-C23/2+E23 -> 12 | AY23: =+ABS((D23-F23)*(E23-G23)) -> 1347.8658 | AZ23: =+ABS((H23-J23)*(I23-K23)) -> 1266 | BA23: =+ABS((L23-N23)*(M23-O23)) -> 1408.96 | BB23: =+(P23-R23)*(Q23-S23) -> -451 | BC23: =+ABS((T23-V23)*(U23-W23))+ABS((X23-Z23)*(Y23-AA23)) -> 1543 | BD23: =+PI()*((AD23+3)^2+(AG23+3)^2+(AJ23+3)^2+(AM23+3)^2+(AP23+3)^2+(AS23+3)^2) -> 169.646 | BE23: =+SUM(AY23:BD23) -> 5284.4718
A24: =+A23+1 -> 22 | B24: TS105-01 | C24: 6 | D24: -173.95 | E24: 15 | F24: 50.6943 | G24: 21 | H24: -150 | I24: 15 | J24: -44.5 | K24: 3 | L24: -85.88 | M24: 43.5 | N24: -3 | O24: 26.5 | P24: -75 | Q24: 26.5 | R24: 7 | S24: 21 | T24: -45 | U24: 15 | V24: -8 | W24: -4 | X24: -45 | Y24: -4 | Z24: -3 | AA24: -24 | AT24: 16 | AU24: =+D24 -> -173.95 | AV24: =-C24/2+E24 -> 12 | AW24: =+F24 -> 50.6943 | AX24: =-C24/2+E24 -> 12 | AY24: =+ABS((D24-F24)*(E24-G24)) -> 1347.8658 | AZ24: =+ABS((H24-J24)*(I24-K24)) -> 1266 | BA24: =+ABS((L24-N24)*(M24-O24)) -> 1408.96 | BB24: =+(P24-R24)*(Q24-S24) -> -451 | BC24: =+ABS((T24-V24)*(U24-W24))+ABS((X24-Z24)*(Y24-AA24)) -> 1543 | BD24: =+PI()*((AD24+3)^2+(AG24+3)^2+(AJ24+3)^2+(AM24+3)^2+(AP24+3)^2+(AS24+3)^2) -> 169.646 | BE24: =+SUM(AY24:BD24) -> 5284.4718
A25: =+A24+1 -> 23 | B25: TS108-05 | C25: 6 | D25: -173.95 | E25: 15 | F25: 50.6943 | G25: 21 | H25: -150 | I25: 15 | J25: -44.5 | K25: 3 | L25: -85.88 | M25: 43.5 | N25: -3 | O25: 26.5 | P25: -75 | Q25: 26.5 | R25: 7 | S25: 21 | T25: -45 | U25: 15 | V25: -8 | W25: -4 | X25: -45 | Y25: -4 | Z25: -3 | AA25: -24 | AT25: 16 | AU25: =+D25 -> -173.95 | AV25: =-C25/2+E25 -> 12 | AW25: =+F25 -> 50.6943 | AX25: =-C25/2+E25 -> 12 | AY25: =+ABS((D25-F25)*(E25-G25)) -> 1347.8658 | AZ25: =+ABS((H25-J25)*(I25-K25)) -> 1266 | BA25: =+ABS((L25-N25)*(M25-O25)) -> 1408.96 | BB25: =+(P25-R25)*(Q25-S25) -> -451 | BC25: =+ABS((T25-V25)*(U25-W25))+ABS((X25-Z25)*(Y25-AA25)) -> 1543 | BD25: =+PI()*((AD25+3)^2+(AG25+3)^2+(AJ25+3)^2+(AM25+3)^2+(AP25+3)^2+(AS25+3)^2) -> 169.646 | BE25: =+SUM(AY25:BD25) -> 5284.4718
A26: =+A25+1 -> 24 | B26: TS125-04 | C26: 6 | D26: -173.95 | E26: 15 | F26: 50.6943 | G26: 21 | H26: -150 | I26: 15 | J26: -44.5 | K26: 3 | L26: -85.88 | M26: 43.5 | N26: -3 | O26: 26.5 | P26: -75 | Q26: 26.5 | R26: 7 | S26: 21 | T26: -45 | U26: 15 | V26: -8 | W26: -4 | X26: -45 | Y26: -4 | Z26: -3 | AA26: -24 | AT26: 16 | AU26: =+D26 -> -173.95 | AV26: =-C26/2+E26 -> 12 | AW26: =+F26 -> 50.6943 | AX26: =-C26/2+E26 -> 12 | AY26: =+ABS((D26-F26)*(E26-G26)) -> 1347.8658 | AZ26: =+ABS((H26-J26)*(I26-K26)) -> 1266 | BA26: =+ABS((L26-N26)*(M26-O26)) -> 1408.96 | BB26: =+(P26-R26)*(Q26-S26) -> -451 | BC26: =+ABS((T26-V26)*(U26-W26))+ABS((X26-Z26)*(Y26-AA26)) -> 1543 | BD26: =+PI()*((AD26+3)^2+(AG26+3)^2+(AJ26+3)^2+(AM26+3)^2+(AP26+3)^2+(AS26+3)^2) -> 169.646 | BE26: =+SUM(AY26:BD26) -> 5284.4718
A27: =+A26+1 -> 25 | B27: TS135-01 | C27: 6 | D27: -173.95 | E27: 15 | F27: 50.6943 | G27: 21 | H27: -150 | I27: 15 | J27: -44.5 | K27: 3 | L27: -85.88 | M27: 43.5 | N27: -3 | O27: 26.5 | P27: -75 | Q27: 26.5 | R27: 7 | S27: 21 | T27: -45 | U27: 15 | V27: -8 | W27: -4 | X27: -45 | Y27: -4 | Z27: -3 | AA27: -24 | AT27: 16 | AU27: =+D27 -> -173.95 | AV27: =-C27/2+E27 -> 12 | AW27: =+F27 -> 50.6943 | AX27: =-C27/2+E27 -> 12 | AY27: =+ABS((D27-F27)*(E27-G27)) -> 1347.8658 | AZ27: =+ABS((H27-J27)*(I27-K27)) -> 1266 | BA27: =+ABS((L27-N27)*(M27-O27)) -> 1408.96 | BB27: =+(P27-R27)*(Q27-S27) -> -451 | BC27: =+ABS((T27-V27)*(U27-W27))+ABS((X27-Z27)*(Y27-AA27)) -> 1543 | BD27: =+PI()*((AD27+3)^2+(AG27+3)^2+(AJ27+3)^2+(AM27+3)^2+(AP27+3)^2+(AS27+3)^2) -> 169.646 | BE27: =+SUM(AY27:BD27) -> 5284.4718
A28: =+A27+1 -> 26 | B28: TS155-02 | C28: 6 | D28: -173.95 | E28: 15 | F28: 50.6943 | G28: 21 | H28: -150 | I28: 15 | J28: -44.5 | K28: 3 | L28: -85.88 | M28: 43.5 | N28: -3 | O28: 26.5 | P28: -75 | Q28: 26.5 | R28: 7 | S28: 21 | T28: -45 | U28: 15 | V28: -8 | W28: -4 | X28: -45 | Y28: -4 | Z28: -3 | AA28: -24 | AT28: 16 | AU28: =+D28 -> -173.95 | AV28: =-C28/2+E28 -> 12 | AW28: =+F28 -> 50.6943 | AX28: =-C28/2+E28 -> 12 | AY28: =+ABS((D28-F28)*(E28-G28)) -> 1347.8658 | AZ28: =+ABS((H28-J28)*(I28-K28)) -> 1266 | BA28: =+ABS((L28-N28)*(M28-O28)) -> 1408.96 | BB28: =+(P28-R28)*(Q28-S28) -> -451 | BC28: =+ABS((T28-V28)*(U28-W28))+ABS((X28-Z28)*(Y28-AA28)) -> 1543 | BD28: =+PI()*((AD28+3)^2+(AG28+3)^2+(AJ28+3)^2+(AM28+3)^2+(AP28+3)^2+(AS28+3)^2) -> 169.646 | BE28: =+SUM(AY28:BD28) -> 5284.4718
A29: =+A28+1 -> 27 | B29: TC120N | C29: 6 | D29: -179.645 | E29: -18 | F29: 38.065 | G29: -24 | H29: -171.552 | I29: -4.249 | J29: -50.5 | K29: -17.909 | L29: -71.538 | M29: -28 | N29: 4.5 | O29: -43 | P29: -71.5 | Q29: -24 | R29: 12.5 | S29: -28 | T29: -50.5 | U29: 5 | V29: -5.5 | W29: -18 | X29: -50.5 | Y29: 17 | Z29: -29.5 | AA29: 5 | AB29: -18.149 | AC29: 9.502 | AD29: 4.7 | AE29: 8.7485 | AF29: 9.63 | AG29: 4.58 | AH29: 0 | AI29: 10.172 | AJ29: 4.037 | AK29: -1.877 | AL29: 9.728 | AM29: 3.7 | AN29: 5.19 | AO29: 7.645 | AP29: 3.262 | AT29: 11.09 | AU29: =+D29 -> -179.645 | AV29: =-C29/2+E29 -> -21 | AW29: =+F29 -> 38.065 | AX29: =-C29/2+E29 -> -21 | AY29: =+ABS((D29-F29)*(E29-G29)) -> 1306.26 | AZ29: =+ABS((H29-J29)*(I29-K29)) -> 1653.5703 | BA29: =+ABS((L29-N29)*(M29-O29)) -> 1140.57 | BB29: =+(P29-R29)*(Q29-S29) -> -336 | BC29: =+ABS((T29-V29)*(U29-W29))+ABS((X29-Z29)*(Y29-AA29)) -> 1287 | BD29: =+PI()*((AD29+3)^2+(AG29+3)^2+(AJ29+3)^2+(AM29+3)^2+(AP29+3)^2+(AS29+3)^2) -> 814.8299 | BE29: =+SUM(AY29:BD29) -> 5866.2302
A30: =+A29+1 -> 28 | B30: TS118-00 | C30: 6 | D30: -179.645 | E30: -18 | F30: 38.065 | G30: -24 | H30: -171.5 | I30: -4 | J30: -50.5 | K30: -18 | L30: -71.5 | M30: -28 | N30: 4.5 | O30: -43 | P30: -71.5 | Q30: -24 | R30: 12.5 | S30: -28 | T30: -50.5 | U30: 17 | V30: -29.5 | W30: 5 | X30: -50.5 | Y30: 5 | Z30: -5.5 | AA30: -18 | AB30: -18.149 | AC30: 9.502 | AD30: 4.7 | AE30: -8.75 | AF30: 9.63 | AG30: 4.58 | AH30: 0 | AI30: 10.17 | AJ30: 4.037 | AK30: -1.877 | AL30: -9.728 | AM30: 3.7 | AN30: 5.19 | AO30: -7.645 | AP30: 3.262 | AT30: 11.09 | AU30: =+D30 -> -179.645 | AV30: =-C30/2+E30 -> -21 | AW30: =+F30 -> 38.065 | AX30: =-C30/2+E30 -> -21 | AY30: =+ABS((D30-F30)*(E30-G30)) -> 1306.26 | AZ30: =+ABS((H30-J30)*(I30-K30)) -> 1694 | BA30: =+ABS((L30-N30)*(M30-O30)) -> 1140 | BB30: =+(P30-R30)*(Q30-S30) -> -336 | BC30: =+ABS((T30-V30)*(U30-W30))+ABS((X30-Z30)*(Y30-AA30)) -> 1287 | BD30: =+PI()*((AD30+3)^2+(AG30+3)^2+(AJ30+3)^2+(AM30+3)^2+(AP30+3)^2+(AS30+3)^2) -> 814.8299 | BE30: =+SUM(AY30:BD30) -> 5906.0899
A31: =+A30+1 -> 29 | B31: TS148-00 | C31: 6 | D31: -179.645 | E31: -18 | F31: 38.065 | G31: -24 | H31: -171.5 | I31: -4 | J31: -50.5 | K31: -18 | L31: -71.5 | M31: -28 | N31: 4.5 | O31: -43 | P31: -71.5 | Q31: -24 | R31: 12.5 | S31: -28 | T31: -50.5 | U31: 17 | V31: -29.5 | W31: 5 | X31: -50.5 | Y31: 5 | Z31: -5.5 | AA31: -18 | AB31: -18.149 | AC31: 9.502 | AD31: 4.7 | AE31: -8.75 | AF31: 9.63 | AG31: 4.58 | AH31: 0 | AI31: 10.17 | AJ31: 4.037 | AK31: -1.877 | AL31: -9.728 | AM31: 3.7 | AN31: 5.19 | AO31: -7.645 | AP31: 3.262 | AT31: 11.09 | AU31: =+D31 -> -179.645 | AV31: =-C31/2+E31 -> -21 | AW31: =+F31 -> 38.065 | AX31: =-C31/2+E31 -> -21 | AY31: =+ABS((D31-F31)*(E31-G31)) -> 1306.26 | AZ31: =+ABS((H31-J31)*(I31-K31)) -> 1694 | BA31: =+ABS((L31-N31)*(M31-O31)) -> 1140 | BB31: =+(P31-R31)*(Q31-S31) -> -336 | BC31: =+ABS((T31-V31)*(U31-W31))+ABS((X31-Z31)*(Y31-AA31)) -> 1287 | BD31: =+PI()*((AD31+3)^2+(AG31+3)^2+(AJ31+3)^2+(AM31+3)^2+(AP31+3)^2+(AS31+3)^2) -> 814.8299 | BE31: =+SUM(AY31:BD31) -> 5906.0899
A32: =+A31+1 -> 30 | B32: TS159-00 | C32: 6 | D32: -179.645 | E32: -18 | F32: 38.065 | G32: -24 | H32: -171.5 | I32: -4 | J32: -50.5 | K32: -18 | L32: -71.5 | M32: -28 | N32: 4.5 | O32: -43 | P32: -71.5 | Q32: -24 | R32: 12.5 | S32: -28 | T32: -50.5 | U32: 17 | V32: -29.5 | W32: 5 | X32: -50.5 | Y32: 5 | Z32: -5.5 | AA32: -18 | AB32: -18.149 | AC32: 9.502 | AD32: 4.7 | AE32: -8.75 | AF32: 9.63 | AG32: 4.58 | AH32: 0 | AI32: 10.17 | AJ32: 4.037 | AK32: -1.877 | AL32: -9.728 | AM32: 3.7 | AN32: 5.19 | AO32: -7.645 | AP32: 3.262 | AT32: 11.09 | AU32: =+D32 -> -179.645 | AV32: =-C32/2+E32 -> -21 | AW32: =+F32 -> 38.065 | AX32: =-C32/2+E32 -> -21 | AY32: =+ABS((D32-F32)*(E32-G32)) -> 1306.26 | AZ32: =+ABS((H32-J32)*(I32-K32)) -> 1694 | BA32: =+ABS((L32-N32)*(M32-O32)) -> 1140 | BB32: =+(P32-R32)*(Q32-S32) -> -336 | BC32: =+ABS((T32-V32)*(U32-W32))+ABS((X32-Z32)*(Y32-AA32)) -> 1287 | BD32: =+PI()*((AD32+3)^2+(AG32+3)^2+(AJ32+3)^2+(AM32+3)^2+(AP32+3)^2+(AS32+3)^2) -> 814.8299 | BE32: =+SUM(AY32:BD32) -> 5906.0899
A33: =+A32+1 -> 31 | B33: TCS164B | C33: 6 | D33: -179.645 | E33: -18 | F33: 38.065 | G33: -24 | H33: -171.5 | I33: -4 | J33: -50.5 | K33: -18 | L33: -71.5 | M33: -28 | N33: 4.5 | O33: -43 | P33: -71.5 | Q33: -24 | R33: 12.5 | S33: -28 | T33: -50.5 | U33: 17 | V33: -29.5 | W33: 5 | X33: -50.5 | Y33: 5 | Z33: -5.5 | AA33: -18 | AB33: -18.149 | AC33: 9.502 | AD33: 4.7 | AE33: -8.75 | AF33: 9.63 | AG33: 4.58 | AH33: 0 | AI33: 10.17 | AJ33: 4.037 | AK33: -1.877 | AL33: -9.728 | AM33: 3.7 | AN33: 5.19 | AO33: -7.645 | AP33: 3.262 | AT33: 11.09 | AU33: =+D33 -> -179.645 | AV33: =-C33/2+E33 -> -21 | AW33: =+F33 -> 38.065 | AX33: =-C33/2+E33 -> -21 | AY33: =+ABS((D33-F33)*(E33-G33)) -> 1306.26 | AZ33: =+ABS((H33-J33)*(I33-K33)) -> 1694 | BA33: =+ABS((L33-N33)*(M33-O33)) -> 1140 | BB33: =+(P33-R33)*(Q33-S33) -> -336 | BC33: =+ABS((T33-V33)*(U33-W33))+ABS((X33-Z33)*(Y33-AA33)) -> 1287 | BD33: =+PI()*((AD33+3)^2+(AG33+3)^2+(AJ33+3)^2+(AM33+3)^2+(AP33+3)^2+(AS33+3)^2) -> 814.8299 | BE33: =+SUM(AY33:BD33) -> 5906.0899
A34: =+A33+1 -> 32 | B34: TCS168N | C34: 6 | D34: -179.645 | E34: -18 | F34: 38.065 | G34: -24 | H34: -171.5 | I34: -4 | J34: -50.5 | K34: -18 | L34: -71.5 | M34: -28 | N34: 4.5 | O34: -43 | P34: -71.5 | Q34: -24 | R34: 12.5 | S34: -28 | T34: -50.5 | U34: 17 | V34: -29.5 | W34: 5 | X34: -50.5 | Y34: 5 | Z34: -5.5 | AA34: -18 | AB34: -18.149 | AC34: 9.502 | AD34: 4.7 | AE34: -8.75 | AF34: 9.63 | AG34: 4.58 | AH34: 0 | AI34: 10.17 | AJ34: 4.037 | AK34: -1.877 | AL34: -9.728 | AM34: 3.7 | AN34: 5.19 | AO34: -7.645 | AP34: 3.262 | AT34: 11.09 | AU34: =+D34 -> -179.645 | AV34: =-C34/2+E34 -> -21 | AW34: =+F34 -> 38.065 | AX34: =-C34/2+E34 -> -21 | AY34: =+ABS((D34-F34)*(E34-G34)) -> 1306.26 | AZ34: =+ABS((H34-J34)*(I34-K34)) -> 1694 | BA34: =+ABS((L34-N34)*(M34-O34)) -> 1140 | BB34: =+(P34-R34)*(Q34-S34) -> -336 | BC34: =+ABS((T34-V34)*(U34-W34))+ABS((X34-Z34)*(Y34-AA34)) -> 1287 | BD34: =+PI()*((AD34+3)^2+(AG34+3)^2+(AJ34+3)^2+(AM34+3)^2+(AP34+3)^2+(AS34+3)^2) -> 814.8299 | BE34: =+SUM(AY34:BD34) -> 5906.0899
A35: =+A34+1 -> 33 | B35: TS118-03 | C35: 6 | D35: -179.645 | E35: -18 | F35: 38.065 | G35: -24 | H35: -171.5 | I35: -4 | J35: -50.5 | K35: -18 | L35: -71.5 | M35: -28 | N35: 4.5 | O35: -43 | P35: -71.5 | Q35: -24 | R35: 12.5 | S35: -28 | T35: -50.5 | U35: 17 | V35: -29.5 | W35: 5 | X35: -50.5 | Y35: 5 | Z35: -5.5 | AA35: -18 | AB35: -18.149 | AC35: 9.502 | AD35: 4.7 | AE35: -8.75 | AF35: 9.63 | AG35: 4.58 | AH35: 0 | AI35: 10.17 | AJ35: 4.037 | AK35: -1.877 | AL35: -9.728 | AM35: 3.7 | AN35: 5.19 | AO35: -7.645 | AP35: 3.262 | AT35: 11.09 | AU35: =+D35 -> -179.645 | AV35: =-C35/2+E35 -> -21 | AW35: =+F35 -> 38.065 | AX35: =-C35/2+E35 -> -21 | AY35: =+ABS((D35-F35)*(E35-G35)) -> 1306.26 | AZ35: =+ABS((H35-J35)*(I35-K35)) -> 1694 | BA35: =+ABS((L35-N35)*(M35-O35)) -> 1140 | BB35: =+(P35-R35)*(Q35-S35) -> -336 | BC35: =+ABS((T35-V35)*(U35-W35))+ABS((X35-Z35)*(Y35-AA35)) -> 1287 | BD35: =+PI()*((AD35+3)^2+(AG35+3)^2+(AJ35+3)^2+(AM35+3)^2+(AP35+3)^2+(AS35+3)^2) -> 814.8299 | BE35: =+SUM(AY35:BD35) -> 5906.0899
A36: =+A35+1 -> 34 | B36: TS138 | C36: 6 | D36: -179.645 | E36: -18 | F36: 38.065 | G36: -24 | H36: -171.5 | I36: -4 | J36: -50.5 | K36: -18 | L36: -71.5 | M36: -28 | N36: 4.5 | O36: -43 | P36: -71.5 | Q36: -24 | R36: 12.5 | S36: -28 | T36: -50.5 | U36: 17 | V36: -29.5 | W36: 5 | X36: -50.5 | Y36: 5 | Z36: -5.5 | AA36: -18 | AB36: -18.149 | AC36: 9.502 | AD36: 4.7 | AE36: -8.75 | AF36: 9.63 | AG36: 4.58 | AH36: 0 | AI36: 10.17 | AJ36: 4.037 | AK36: -1.877 | AL36: -9.728 | AM36: 3.7 | AN36: 5.19 | AO36: -7.645 | AP36: 3.262 | AT36: 11.09 | AU36: =+D36 -> -179.645 | AV36: =-C36/2+E36 -> -21 | AW36: =+F36 -> 38.065 | AX36: =-C36/2+E36 -> -21 | AY36: =+ABS((D36-F36)*(E36-G36)) -> 1306.26 | AZ36: =+ABS((H36-J36)*(I36-K36)) -> 1694 | BA36: =+ABS((L36-N36)*(M36-O36)) -> 1140 | BB36: =+(P36-R36)*(Q36-S36) -> -336 | BC36: =+ABS((T36-V36)*(U36-W36))+ABS((X36-Z36)*(Y36-AA36)) -> 1287 | BD36: =+PI()*((AD36+3)^2+(AG36+3)^2+(AJ36+3)^2+(AM36+3)^2+(AP36+3)^2+(AS36+3)^2) -> 814.8299 | BE36: =+SUM(AY36:BD36) -> 5906.0899
A37: =+A36+1 -> 35 | B37: TS148-01 | C37: 6 | D37: -179.645 | E37: -18 | F37: 38.065 | G37: -24 | H37: -171.5 | I37: -4 | J37: -50.5 | K37: -18 | L37: -71.5 | M37: -28 | N37: 4.5 | O37: -43 | P37: -71.5 | Q37: -24 | R37: 12.5 | S37: -28 | T37: -50.5 | U37: 17 | V37: -29.5 | W37: 5 | X37: -50.5 | Y37: 5 | Z37: -5.5 | AA37: -18 | AB37: -18.149 | AC37: 9.502 | AD37: 4.7 | AE37: -8.75 | AF37: 9.63 | AG37: 4.58 | AH37: 0 | AI37: 10.17 | AJ37: 4.037 | AK37: -1.877 | AL37: -9.728 | AM37: 3.7 | AN37: 5.19 | AO37: -7.645 | AP37: 3.262 | AT37: 11.09 | AU37: =+D37 -> -179.645 | AV37: =-C37/2+E37 -> -21 | AW37: =+F37 -> 38.065 | AX37: =-C37/2+E37 -> -21 | AY37: =+ABS((D37-F37)*(E37-G37)) -> 1306.26 | AZ37: =+ABS((H37-J37)*(I37-K37)) -> 1694 | BA37: =+ABS((L37-N37)*(M37-O37)) -> 1140 | BB37: =+(P37-R37)*(Q37-S37) -> -336 | BC37: =+ABS((T37-V37)*(U37-W37))+ABS((X37-Z37)*(Y37-AA37)) -> 1287 | BD37: =+PI()*((AD37+3)^2+(AG37+3)^2+(AJ37+3)^2+(AM37+3)^2+(AP37+3)^2+(AS37+3)^2) -> 814.8299 | BE37: =+SUM(AY37:BD37) -> 5906.0899
A38: =+A37+1 -> 36 | B38: TS159-01 | C38: 6 | D38: -179.645 | E38: -18 | F38: 38.065 | G38: -24 | H38: -171.5 | I38: -4 | J38: -50.5 | K38: -18 | L38: -71.5 | M38: -28 | N38: 4.5 | O38: -43 | P38: -71.5 | Q38: -24 | R38: 12.5 | S38: -28 | T38: -50.5 | U38: 17 | V38: -29.5 | W38: 5 | X38: -50.5 | Y38: 5 | Z38: -5.5 | AA38: -18 | AB38: -18.149 | AC38: 9.502 | AD38: 4.7 | AE38: -8.75 | AF38: 9.63 | AG38: 4.58 | AH38: 0 | AI38: 10.17 | AJ38: 4.037 | AK38: -1.877 | AL38: -9.728 | AM38: 3.7 | AN38: 5.19 | AO38: -7.645 | AP38: 3.262 | AT38: 11.09 | AU38: =+D38 -> -179.645 | AV38: =-C38/2+E38 -> -21 | AW38: =+F38 -> 38.065 | AX38: =-C38/2+E38 -> -21 | AY38: =+ABS((D38-F38)*(E38-G38)) -> 1306.26 | AZ38: =+ABS((H38-J38)*(I38-K38)) -> 1694 | BA38: =+ABS((L38-N38)*(M38-O38)) -> 1140 | BB38: =+(P38-R38)*(Q38-S38) -> -336 | BC38: =+ABS((T38-V38)*(U38-W38))+ABS((X38-Z38)*(Y38-AA38)) -> 1287 | BD38: =+PI()*((AD38+3)^2+(AG38+3)^2+(AJ38+3)^2+(AM38+3)^2+(AP38+3)^2+(AS38+3)^2) -> 814.8299 | BE38: =+SUM(AY38:BD38) -> 5906.0899
A39: =+A38+1 -> 37 | B39: TS112 | C39: 6 | D39: -179.645 | E39: -18 | F39: 38.065 | G39: -24 | H39: -171.5 | I39: -4 | J39: -50.5 | K39: -18 | L39: -71.5 | M39: -28 | N39: 4.5 | O39: -43 | P39: -71.5 | Q39: -24 | R39: 12.5 | S39: -28 | T39: -50.5 | U39: 17 | V39: -29.5 | W39: 5 | X39: -50.5 | Y39: 5 | Z39: -5.5 | AA39: -18 | AB39: -18.149 | AC39: 9.502 | AD39: 4.7 | AE39: -8.75 | AF39: 9.63 | AG39: 4.58 | AH39: 0 | AI39: 10.17 | AJ39: 4.037 | AK39: -1.877 | AL39: -9.728 | AM39: 3.7 | AN39: 5.19 | AO39: -7.645 | AP39: 3.262 | AT39: 11.09 | AU39: =+D39 -> -179.645 | AV39: =-C39/2+E39 -> -21 | AW39: =+F39 -> 38.065 | AX39: =-C39/2+E39 -> -21 | AY39: =+ABS((D39-F39)*(E39-G39)) -> 1306.26 | AZ39: =+ABS((H39-J39)*(I39-K39)) -> 1694 | BA39: =+ABS((L39-N39)*(M39-O39)) -> 1140 | BB39: =+(P39-R39)*(Q39-S39) -> -336 | BC39: =+ABS((T39-V39)*(U39-W39))+ABS((X39-Z39)*(Y39-AA39)) -> 1287 | BD39: =+PI()*((AD39+3)^2+(AG39+3)^2+(AJ39+3)^2+(AM39+3)^2+(AP39+3)^2+(AS39+3)^2) -> 814.8299 | BE39: =+SUM(AY39:BD39) -> 5906.0899
A40: =+A39+1 -> 38 | B40: TS142-00 | C40: 6 | D40: -179.645 | E40: -18 | F40: 38.065 | G40: -24 | H40: -171.5 | I40: -4 | J40: -50.5 | K40: -18 | L40: -71.5 | M40: -28 | N40: 4.5 | O40: -43 | P40: -71.5 | Q40: -24 | R40: 12.5 | S40: -28 | T40: -50.5 | U40: 17 | V40: -29.5 | W40: 5 | X40: -50.5 | Y40: 5 | Z40: -5.5 | AA40: -18 | AB40: -18.149 | AC40: 9.502 | AD40: 4.7 | AE40: -8.75 | AF40: 9.63 | AG40: 4.58 | AH40: 0 | AI40: 10.17 | AJ40: 4.037 | AK40: -1.877 | AL40: -9.728 | AM40: 3.7 | AN40: 5.19 | AO40: -7.645 | AP40: 3.262 | AT40: 11.09 | AU40: =+D40 -> -179.645 | AV40: =-C40/2+E40 -> -21 | AW40: =+F40 -> 38.065 | AX40: =-C40/2+E40 -> -21 | AY40: =+ABS((D40-F40)*(E40-G40)) -> 1306.26 | AZ40: =+ABS((H40-J40)*(I40-K40)) -> 1694 | BA40: =+ABS((L40-N40)*(M40-O40)) -> 1140 | BB40: =+(P40-R40)*(Q40-S40) -> -336 | BC40: =+ABS((T40-V40)*(U40-W40))+ABS((X40-Z40)*(Y40-AA40)) -> 1287 | BD40: =+PI()*((AD40+3)^2+(AG40+3)^2+(AJ40+3)^2+(AM40+3)^2+(AP40+3)^2+(AS40+3)^2) -> 814.8299 | BE40: =+SUM(AY40:BD40) -> 5906.0899
... A44: =+A43+1 -> 42 | B44: TS108-04 | C44: 6 | D44: -179.645 | E44: -18 | F44: 38.065 | G44: -24 | H44: -171.5 | I44: -4 | J44: -50.5 | K44: -18 | L44: -71.5 | M44: -28 | N44: 4.5 | O44: -43 | P44: -71.5 | Q44: -24 | R44: 12.5 | S44: -28 | T44: -50.5 | U44: 17 | V44: -29.5 | W44: 5 | X44: -50.5 | Y44: 5 | Z44: -5.5 | AA44: -18 | AB44: -18.149 | AC44: 9.502 | AD44: 4.7 | AE44: -8.75 | AF44: 9.63 | AG44: 4.58 | AH44: 0 | AI44: 10.17 | AJ44: 4.037 | AK44: -1.877 | AL44: -9.728 | AM44: 3.7 | AN44: 5.19 | AO44: -7.645 | AP44: 3.262 | AT44: 11.09 | AU44: =+D44 -> -179.645 | AV44: =-C44/2+E44 -> -21 | AW44: =+F44 -> 38.065 | AX44: =-C44/2+E44 -> -21 | AY44: =+ABS((D44-F44)*(E44-G44)) -> 1306.26 | AZ44: =+ABS((H44-J44)*(I44-K44)) -> 1694 | BA44: =+ABS((L44-N44)*(M44-O44)) -> 1140 | BB44: =+(P44-R44)*(Q44-S44) -> -336 | BC44: =+ABS((T44-V44)*(U44-W44))+ABS((X44-Z44)*(Y44-AA44)) -> 1287 | BD44: =+PI()*((AD44+3)^2+(AG44+3)^2+(AJ44+3)^2+(AM44+3)^2+(AP44+3)^2+(AS44+3)^2) -> 814.8299 | BE44: =+SUM(AY44:BD44) -> 5906.0899
A45: =+A44+1 -> 43 | B45: TS119 | C45: 6 | D45: -178.88 | E45: -15 | F45: 67.693 | G45: -21 | H45: -162 | I45: -1 | J45: -57 | K45: -15 | L45: -84 | M45: -28 | N45: -1 | O45: -43 | P45: -67 | Q45: -21 | R45: 7 | S45: -28 | T45: -57 | U45: 4 | V45: -4 | W45: -15 | X45: -57 | Y45: 20.168 | Z45: -4 | AA45: 4 | AT45: =13.3*2 -> 26.6 | AU45: =+D45 -> -178.88 | AV45: =-C45/2+E45 -> -18 | AW45: =+F45 -> 67.693 | AX45: =-C45/2+E45 -> -18 | AY45: =+ABS((D45-F45)*(E45-G45)) -> 1479.438 | AZ45: =+ABS((H45-J45)*(I45-K45)) -> 1470 | BA45: =+ABS((L45-N45)*(M45-O45)) -> 1245 | BB45: =+(P45-R45)*(Q45-S45) -> -518 | BC45: =+ABS((T45-V45)*(U45-W45))+ABS((X45-Z45)*(Y45-AA45)) -> 1863.904
...
